<?xml version="1.0"?>
 <robot name="abb_irb6640" xmlns:xacro="http://ros.org/wiki/xacro">
     <link name="base_link">
      <visual>
        <origin xyz="0 0 0" rpy="0 0 0" />
        <geometry>
          <mesh filename="package://abb_irb6600_support/meshes/irb6600_225_255/visual/base_link.stl" />
        </geometry>
        <material name="orange">
          <color rgba="1 0.43 0 1"/>
        </material>
      </visual>
      <collision>
        <origin xyz="0 0 0" rpy="0 0 0" />
        <geometry>
          <mesh filename="package://abb_irb6600_support/meshes/irb6600_225_255/collision/base_link.stl" />
        </geometry>
        <material name="yellow">
          <color rgba="0 1 1 1"/>
        </material>
      </collision>
    </link>
    <link name="link_1">
      <visual>
        <origin xyz="0 0 0" rpy="0 0 0" />
        <geometry>
          <mesh filename="package://abb_irb6600_support/meshes/irb6600_225_255/visual/link_1.stl" />
        </geometry>
        <material name="orange">
          <color rgba="1 0.43 0 1"/>
        </material>
      </visual>
      <collision>
        <origin xyz="0 0 0" rpy="0 0 0" />
        <geometry>
          <mesh filename="package://abb_irb6600_support/meshes/irb6600_225_255/collision/link_1.stl" />
        </geometry>
        <material name="yellow">
          <color rgba="0 1 1 1"/>
        </material>
      </collision>
    </link>
    <link name="link_1_mtr">
      <visual>
        <origin xyz="0 0 0" rpy="0 0 0" />
        <geometry>
          <mesh filename="package://abb_irb6600_support/meshes/irb6600_225_255/visual/link_1_mtr.stl" />
        </geometry>
        <material name="orange">
          <color rgba="1 0.43 0 1"/>
        </material>
      </visual>
      <collision>
        <origin xyz="0 0 0" rpy="0 0 0" />
        <geometry>
          <mesh filename="package://abb_irb6600_support/meshes/irb6600_225_255/collision/link_1_mtr.stl" />
        </geometry>
        <material name="yellow">
          <color rgba="0 1 1 1"/>
        </material>
      </collision>
    </link>
    <link name="link_1_mtr2">
      <visual>
        <origin xyz="0 0 0" rpy="0 0 0" />
        <geometry>
          <mesh filename="package://abb_irb6600_support/meshes/irb6600_225_255/visual/link_1_mtr2.stl" />
        </geometry>
        <material name="orange">
          <color rgba="1 0.43 0 1"/>
        </material>
      </visual>
      <collision>
        <origin xyz="0 0 0" rpy="0 0 0" />
        <geometry>
          <mesh filename="package://abb_irb6600_support/meshes/irb6600_225_255/collision/link_1_mtr2.stl" />
        </geometry>
        <material name="yellow">
          <color rgba="0 1 1 1"/>
        </material>
      </collision>
    </link>
    <link name="link_1_wt">
      <visual>
        <origin xyz="0 0 0" rpy="0 0 0" />
        <geometry>
          <mesh filename="package://abb_irb6600_support/meshes/irb6600_225_255/visual/link_1_wt.stl" />
        </geometry>
        <material name="orange">
          <color rgba="1 0.43 0 1"/>
        </material>>
      </visual>
      <collision>
        <origin xyz="0 0 0" rpy="0 0 0" />
        <geometry>
          <mesh filename="package://abb_irb6600_support/meshes/irb6600_225_255/collision/link_1_wt.stl" />
        </geometry>
        <material name="orange">
          <color rgba="1 0.43 0 1"/>
        </material>
      </collision>
    </link>
    <link name="link_2">
      <visual>
        <origin xyz="0 0 0" rpy="0 0 0" />
        <geometry>
          <mesh filename="package://abb_irb6600_support/meshes/irb6600_225_255/visual/link_2.stl" />
        </geometry>
        <material name="orange">
          <color rgba="1 0.43 0 1"/>
        </material>
      </visual>
      <collision>
        <origin xyz="0 0 0" rpy="0 0 0" />
        <geometry>
          <mesh filename="package://abb_irb6600_support/meshes/irb6600_225_255/collision/link_2.stl" />
        </geometry>
        <material name="yellow">
          <color rgba="0 1 1 1"/>
        </material>
      </collision>
    </link>
    <link name="link_3">
      <visual>
        <origin xyz="0 0 0" rpy="0 0 0" />
        <geometry>
          <mesh filename="package://abb_irb6600_support/meshes/irb6600_225_255/visual/link_3.stl" />
        </geometry>
        <material name="orange">
          <color rgba="1 0.43 0 1"/>
        </material>
      </visual>
      <collision>
        <origin xyz="0 0 0" rpy="0 0 0" />
        <geometry>
          <mesh filename="package://abb_irb6600_support/meshes/irb6600_225_255/collision/link_3.stl" />
        </geometry>
       <material name="yellow">
          <color rgba="0 1 1 1"/>
        </material>
      </collision>
    </link>
    <link name="link_3_mtr">
      <visual>
        <origin xyz="0 0 0" rpy="0 0 0" />
        <geometry>
          <mesh filename="package://abb_irb6600_support/meshes/irb6600_225_255/visual/link_3_mtr.stl" />
        </geometry>
        <material name="orange">
          <color rgba="1 0.43 0 1"/>
        </material>
      </visual>
      <collision>
        <origin xyz="0 0 0" rpy="0 0 0" />
        <geometry>
          <mesh filename="package://abb_irb6600_support/meshes/irb6600_225_255/collision/link_3_mtr.stl" />
        </geometry>
        <material name="yellow">
          <color rgba="0 1 1 1"/>
        </material>
      </collision>
    </link>
    <link name="link_3_mtr2">
      <visual>
        <origin xyz="0 0 0" rpy="0 0 0" />
        <geometry>
          <mesh filename="package://abb_irb6600_support/meshes/irb6600_225_255/visual/link_3_mtr2.stl" />
        </geometry>
        <material name="orange">
          <color rgba="1 0.43 0 1"/>
        </material>/>
      </visual>
      <collision>
        <origin xyz="0 0 0" rpy="0 0 0" />
        <geometry>
          <mesh filename="package://abb_irb6600_support/meshes/irb6600_225_255/collision/link_3_mtr2.stl" />
        </geometry>
        <material name="yellow">
          <color rgba="0 1 1 1"/>
        </material>
      </collision>
    </link>
    <link name="link_3_abb">
      <visual>
        <origin xyz="0 0 0" rpy="0 0 0" />
        <geometry>
          <mesh filename="package://abb_irb6600_support/meshes/irb6600_225_255/visual/link_3_abb.stl" />
        </geometry>
        <material name="orange">
          <color rgba="1 0.43 0 1"/>
        </material>
      </visual>
      <collision>
        <origin xyz="0 0 0" rpy="0 0 0" />
        <geometry>
          <mesh filename="package://abb_irb6600_support/meshes/irb6600_225_255/collision/link_3_abb.stl" />
        </geometry>
        <material name="yellow">
          <color rgba="0 1 1 1"/>
        </material>
      </collision>
    </link>
    <link name="link_4">
      <visual>
        <origin xyz="0 0 0" rpy="0 0 0" />
        <geometry>
          <mesh filename="package://abb_irb6600_support/meshes/irb6600_225_255/visual/link_4.stl" />
        </geometry>
        <material name="orange">
          <color rgba="1 0.43 0 1"/>
        </material>/>
      </visual>
      <collision>
        <origin xyz="0 0 0" rpy="0 0 0" />
        <geometry>
          <mesh filename="package://abb_irb6600_support/meshes/irb6600_225_255/collision/link_4.stl" />
        </geometry>
        <material name="yellow">
          <color rgba="0 1 1 1"/>
        </material>
      </collision>
    </link>
    <link name="link_4_abb">
      <visual>
        <origin xyz="0 0 0" rpy="0 0 0" />
        <geometry>
          <mesh filename="package://abb_irb6600_support/meshes/irb6600_225_255/visual/link_4_abb.stl" />
        </geometry>
        <material name="orange">
          <color rgba="1 0.43 0 1"/>
        </material>
      </visual>
      <collision>
        <origin xyz="0 0 0" rpy="0 0 0" />
        <geometry>
          <mesh filename="package://abb_irb6600_support/meshes/irb6600_225_255/collision/link_4_abb.stl" />
        </geometry>
        <material name="yellow">
          <color rgba="0 1 1 1"/>
        </material>
      </collision>
    </link>
    <link name="link_4_abb2">
      <visual>
        <origin xyz="0 0 0" rpy="0 0 0" />
        <geometry>
          <mesh filename="package://abb_irb6600_support/meshes/irb6600_225_255/visual/link_4_abb2.stl" />
        </geometry>
        <material name="orange">
          <color rgba="1 0.43 0 1"/>
        </material>
      </visual>
      <collision>
        <origin xyz="0 0 0" rpy="0 0 0" />
        <geometry>
          <mesh filename="package://abb_irb6600_support/meshes/irb6600_225_255/collision/link_4_abb2.stl" />
        </geometry>
        <material name="yellow">
          <color rgba="0 1 1 1"/>
        </material>
      </collision>
    </link>
    <link name="link_5">
      <visual>
        <origin xyz="0 0 0" rpy="0 0 0" />
        <geometry>
          <mesh filename="package://abb_irb6600_support/meshes/irb6600_225_255/visual/link_5.stl" />
        </geometry>
        <material name="orange">
          <color rgba="1 0.43 0 1"/>
        </material>
      </visual>
      <collision>
        <origin xyz="0 0 0" rpy="0 0 0" />
        <geometry>
          <mesh filename="package://abb_irb6600_support/meshes/irb6600_225_255/collision/link_5.stl" />
        </geometry>
        <material name="yellow">
          <color rgba="0 1 1 1"/>
        </material>
      </collision>
    </link>
    <link name="link_6">
      <visual>
        <origin xyz="0 0 0" rpy="0 0 0" />
        <geometry>
          <mesh filename="package://abb_irb6600_support/meshes/irb6600_225_255/visual/link_6.stl" />
        </geometry>
        <material name="orange">
          <color rgba="1 0.43 0 1"/>
        </material>
      </visual>
      <collision>
        <origin xyz="0 0 0" rpy="0 0 0" />
        <geometry>
          <mesh filename="package://abb_irb6600_support/meshes/irb6600_225_255/collision/link_6.stl" />
        </geometry>
        <material name="yellow">
          <color rgba="0 1 1 1"/>
        </material>
      </collision>
    </link>
    <link name="tool0" />
    <!-- end of link list -->

    <!-- joint list -->
    <joint name="joint_1" type="revolute">
      <origin xyz="0 0 0" rpy="0 0 0" />
      <parent link="base_link" />
      <child link="link_1" />
      <axis xyz="0 0 1" />
      <limit lower="-3.14159265" upper="3.14159265" effort="0" velocity="1.74532925" />
    </joint>
    <joint name="joint_1_mtr" type="fixed">
      <origin xyz="0 0 0" rpy="0 0 0" />
      <parent link="link_1" />
      <child link="link_1_mtr" />
    </joint>
    <joint name="joint_1_mtr2" type="fixed">
      <origin xyz="0 0 0" rpy="0 0 0" />
      <parent link="link_1" />
      <child link="link_1_mtr2" />
    </joint>
    <joint name="joint_1_wt" type="fixed">
      <origin xyz="0 0 0" rpy="0 0 0" />
      <parent link="link_1" />
      <child link="link_1_wt" />
    </joint>
    <joint name="joint_2" type="revolute">
      <origin xyz="0.320 0 0.780" rpy="0 0 0" />
      <parent link="link_1" />
      <child link="link_2" />
      <axis xyz="0 1 0" />
      <limit lower="-1.13446401" upper="1.3962634" effort="0" velocity="1.57079633" />
    </joint>
    <joint name="joint_3" type="revolute">
      <origin xyz="0 0 1.075" rpy="0 0 0" />
      <parent link="link_2" />
      <child link="link_3" />
      <axis xyz="0 1 0" />
      <limit lower="-3.14159265" upper="1.04719755" effort="0" velocity="1.57079633" />
    </joint>
    <joint name="joint_3_mtr" type="fixed">
      <origin xyz="0 0 0" rpy="0 0 0" />
      <parent link="link_3" />
      <child link="link_3_mtr" />
    </joint>
    <joint name="joint_3_mtr2" type="fixed">
      <origin xyz="0 0 0" rpy="0 0 0" />
      <parent link="link_3" />
      <child link="link_3_mtr2" />
    </joint>
    <joint name="joint_3_abb" type="fixed">
      <origin xyz="0 0 0" rpy="0 0 0" />
      <parent link="link_3" />
      <child link="link_3_abb" />
    </joint>
    <joint name="joint_4" type="revolute">
      <origin xyz="0 0 0.2" rpy="0 0 0" />
      <parent link="link_3" />
      <child link="link_4" />
      <axis xyz="1 0 0" />
      <limit lower="-5.23598776" upper="5.23598776" effort="0" velocity="2.61799388" />
    </joint>
    <joint name="joint_4_abb" type="fixed">
      <origin xyz="0 0 0" rpy="0 0 0" />
      <parent link="link_4" />
      <child link="link_4_abb" />
    </joint>
    <joint name="joint_4_abb2" type="fixed">
      <origin xyz="0 0 0" rpy="0 0 0" />
      <parent link="link_4" />
      <child link="link_4_abb2" />
    </joint>
    <joint name="joint_5" type="revolute">
      <origin xyz="1.142 0 0" rpy="0 0 0" />
      <parent link="link_4" />
      <child link="link_5" />
      <axis xyz="0 1 0" />
      <limit lower="-2.0943951" upper="2.0943951" effort="0" velocity="2.0943951" />
    </joint>
    <joint name="joint_6" type="revolute">
      <origin xyz="0.2 0 0" rpy="0 0 0" />
      <parent link="link_5" />
      <child link="link_6" />
      <axis xyz="1 0 0" />
      <limit lower="-5.23598776" upper="5.23598776" effort="0" velocity="3.31612558" />
    </joint>
    <joint name="joint_6-tool0" type="fixed">
      <origin xyz="0 0 0" rpy="0 1.57079632679 0" />
      <parent link="link_6" />
      <child link="tool0" />
    </joint>
    <!-- end of joint list -->

    <!-- ROS base_link to ABB base coordinate system transform -->
    <link name="base" />
    <joint name="base_link-base" type="fixed">
      <origin xyz="0 0 0" rpy="0 0 0"/>
      <parent link="base_link"/>
      <child link="base"/>
    </joint>

</robot>

